Workbook

Sheet Raw_Data
A1: Client ID | B1: Name | C1: Age | D1: Location ID | E1: Joined Bank | F1: Banking Contact | G1: Nationality | H1: Occupation | I1: Fee Structure | J1: Loyalty Classification | K1: Estimated Income | L1: Superannuation Savings | M1: Amount of Credit Cards | N1: Credit Card Balance | O1: Bank Loans | P1: Bank Deposits | Q1: Checking Accounts | R1: Saving Accounts | S1: Foreign Currency Account | T1: Business Lending | U1: Properties Owned | V1: Risk Weighting | W1: BRId | X1: GenderId | Y1: IAId
A2: IND81288 | B2: Raymond Mills | C2: 24 | D2: 34324 | E2: 43591 | F2: Anthony Torres | G2: American | H2: Safety Technician IV | I2: High | J2: Jade | K2: 75384.77 | L2: 17677.95 | M2: 1 | N2: 484.54 | O2: 776242.92 | P2: 1485828.6 | Q2: 603617.88 | R2: 607332.46 | S2: 12249.96 | T2: 1134475.3 | U2: 1 | V2: 2 | W2: 1 | X2: 1 | Y2: 1
A3: IND65833 | B3: Julia Spencer | C3: 23 | D3: 42205 | E3: 37235 | F3: Jonathan Hawkins | G3: African | H3: Software Consultant | I3: High | J3: Jade | K3: 289834.31 | L3: 17398.92 | M3: 1 | N3: 2256.88 | O3: 1270615.4 | P3: 641482.79 | Q3: 229521.37 | R3: 344635.16 | S3: 61162.31 | T3: 2000526.1 | U3: 1 | V3: 3 | W3: 2 | X3: 1 | Y3: 2
A4: IND47499 | B4: Stephen Murray | C4: 27 | D4: 7314 | E4: 40203 | F4: Anthony Berry | G4: European | H4: Help Desk Operator | I4: High | J4: Gold | K4: 169935.23 | L4: 42825.9 | M4: 2 | N4: 4568.74 | O4: 1052715.8 | P4: 1033401.6 | Q4: 652674.69 | R4: 203054.35 | S4: 79071.78 | T4: 548137.58 | U4: 1 | V4: 3 | W4: 3 | X4: 2 | Y4: 3
A5: IND72498 | B5: Virginia Garza | C5: 40 | D5: 34594 | E5: 43552 | F5: Steve Diaz | G5: American | H5: Geologist II | I5: Mid | J5: Silver | K5: 356808.11 | L5: 5473.15 | M5: 2 | N5: 4205 | O5: 121195.06 | P5: 1048157.5 | Q5: 1048157.5 | R5: 234685.02 | S5: 57513.65 | T5: 1148402.3 | U5: 0 | V5: 4 | W5: 4 | X5: 1 | Y5: 4
A6: IND60181 | B6: Melissa Sanders | C6: 46 | D6: 41269 | E6: 41110 | F6: Shawn Long | G6: American | H6: Assistant Professor | I6: Mid | J6: Platinum | K6: 130711.68 | L6: 48077.6 | M6: 1 | N6: 3779.49 | O6: 1048301.9 | P6: 487782.53 | Q6: 446644.25 | R6: 128351.45 | S6: 30012.14 | T6: 1674412.1 | U6: 0 | V6: 3 | W6: 1 | X6: 2 | Y6: 5
A7: IND78532 | B7: Samuel Hudson | C7: 23 | D7: 13204 | E7: 43503 | F7: Douglas Tucker | G7: American | H7: Help Desk Technician | I7: High | J7: Silver | K7: 118326.96 | L7: 6028.2 | M7: 2 | N7: 5148.56 | O7: 601902.5 | P7: 1307269.4 | Q7: 745627.74 | R7: 238310.37 | S7: 15615.18 | T7: 1556031.1 | U7: 1 | V7: 2 | W7: 1 | X7: 1 | Y7: 6
A8: IND95683 | B8: Timothy Alexander | C8: 46 | D8: 42910 | E8: 37409 | F8: Douglas Tucker | G8: Asian | H8: Account Coordinator | I8: High | J8: Gold | K8: 57336.47 | L8: 13929.16 | M8: 1 | N8: 959.9 | O8: 208909.69 | P8: 41200.18 | Q8: 60588.5 | R8: 24639.33 | S8: 3045.78 | T8: 154111.62 | U8: 1 | V8: 1 | W8: 1 | X8: 2 | Y8: 7
A9: IND40785 | B9: Carl Martin | C9: 78 | D9: 6127 | E9: 36833 | F9: Steve Diaz | G9: European | H9: Automation Specialist II | I9: Mid | J9: Gold | K9: 65125.8 | L9: 31077.8 | M9: 1 | N9: 4576.58 | O9: 1140704.8 | P9: 156983.13 | Q9: 53889.73 | R9: 46813.78 | S9: 51979.19 | T9: 1171456.7 | U9: 0 | V9: 2 | W9: 2 | X9: 2 | Y9: 8
A10: IND13570 | B10: Philip Day | C10: 67 | D10: 32656 | E10: 42101 | F10: Bruce Butler | G10: Asian | H10: Software Test Engineer II | I10: High | J10: Silver | K10: 87849.47 | L10: 9385.35 | M10: 1 | N10: 78.62 | O10: 803444.46 | P10: 1242347.2 | Q10: 328334.62 | R10: 279528.12 | S10: 27125.28 | T10: 464560.28 | U10: 0 | V10: 1 | W10: 2 | X10: 2 | Y10: 9
A11: IND53299 | B11: Jason Sims | C11: 51 | D11: 28340 | E11: 35023 | F11: Joe Price | G11: European | H11: Geologist III | I11: Mid | J11: Silver | K11: 65369.36 | L11: 27364.8 | M11: 3 | N11: 4836.86 | O11: 60027.9 | P11: 317246.67 | Q11: 111532.03 | R11: 115869.39 | S11: 48043.52 | T11: 908583.94 | U11: 2 | V11: 1 | W11: 3 | X11: 1 | Y11: 10
A12: IND76263 | B12: Amy Martinez | C12: 55 | D12: 40459 | E12: 41930 | F12: Adam Hernandez | G12: European | H12: Administrative Officer | I12: High | J12: Jade | K12: 74966.51 | L12: 16928.73 | M12: 1 | N12: 493.32 | O12: 214327.82 | P12: 37979.77 | Q12: 19335.16 | R12: 52204.92 | S12: 10539.79 | T12: 353119.93 | U12: 3 | V12: 1 | W12: 3 | X12: 1 | Y12: 11
A13: IND56452 | B13: David Johnston | C13: 73 | D13: 25563 | E13: 38607 | F13: Chris Armstrong | G13: American | H13: Database Administrator II | I13: Mid | J13: Jade | K13: 111449.06 | L13: 17480.19 | M13: 2 | N13: 392.59 | O13: 580468.51 | P13: 749007.94 | Q13: 204991.65 | R13: 513425.24 | S13: 22904.91 | T13: 294397.85 | U13: 0 | V13: 2 | W13: 3 | X13: 2 | Y13: 12
... A3001: IND40216 | B3001: Amy Nguyen | C3001: 79 | D3001: 38518 | E3001: 38694 | F3001: Joe Hanson | G3001: American | H3001: Biostatistician III | I3001: High | J3001: Jade | K3001: 56826.53 | L3001: 8855.3 | M3001: 1 | N3001: 1494.69 | O3001: 285640.66 | P3001: 65617.66 | Q3001: 77769.08 | R3001: 32371.38 | S3001: 8992.36 | T3001: 329412.55 | U3001: 1 | V3001: 1 | W3001: 3 | X3001: 2 | Y3001: 8

Sheet Audit
A1: Column Names | B1: Missing Values | C1: Data Type
A2: Client ID | B2: =COUNTBLANK(Raw_Data!A$2:A$3001) -> 0 | C2: Text
A3: Name | B3: =COUNTBLANK(Raw_Data!B$2:B$3001) -> 0 | C3: Text
A4: Age | B4: =COUNTBLANK(Raw_Data!C$2:C$3001) -> 0 | C4: Number
A5: Location ID | B5: =COUNTBLANK(Raw_Data!D$2:D$3001) -> 0 | C5: Number
A6: Joined Bank | B6: =COUNTBLANK(Raw_Data!E$2:E$3001) -> 0 | C6: Date
A7: Banking Contact | B7: =COUNTBLANK(Raw_Data!F$2:F$3001) -> 0 | C7: Text
A8: Nationality | B8: =COUNTBLANK(Raw_Data!G$2:G$3001) -> 0 | C8: Text
A9: Occupation | B9: =COUNTBLANK(Raw_Data!H$2:H$3001) -> 0 | C9: Text
A10: Fee Structure | B10: =COUNTBLANK(Raw_Data!I$2:I$3001) -> 0 | C10: Text
A11: Loyalty Classification | B11: =COUNTBLANK(Raw_Data!J$2:J$3001) -> 0 | C11: Text
A12: Estimated Income | B12: =COUNTBLANK(Raw_Data!K$2:K$3001) -> 0 | C12: Number
A13: Superannuation Savings | B13: =COUNTBLANK(Raw_Data!L$2:L$3001) -> 0 | C13: Number
A14: Amount of Credit Cards | B14: =COUNTBLANK(Raw_Data!M$2:M$3001) -> 0 | C14: Number
A15: Credit Card Balance | B15: =COUNTBLANK(Raw_Data!N$2:N$3001) -> 0 | C15: Number
A16: Bank Loans | B16: =COUNTBLANK(Raw_Data!O$2:O$3001) -> 0 | C16: Number
A17: Bank Deposits | B17: =COUNTBLANK(Raw_Data!P$2:P$3001) -> 0 | C17: Number
A18: Checking Accounts | B18: =COUNTBLANK(Raw_Data!Q$2:Q$3001) -> 0 | C18: Number
A19: Saving Accounts | B19: =COUNTBLANK(Raw_Data!R$2:R$3001) -> 0 | C19: Number
A20: Foreign Currency Account | B20: =COUNTBLANK(Raw_Data!S$2:S$3001) -> 0 | C20: Number
A21: Business Lending | B21: =COUNTBLANK(Raw_Data!T$2:T$3001) -> 0 | C21: Number
A22: Properties Owned | B22: =COUNTBLANK(Raw_Data!U$2:U$3001) -> 0 | C22: Number
A23: Risk Weighting | B23: =COUNTBLANK(Raw_Data!V$2:V$3001) -> 0 | C23: Number
A24: BRId | B24: =COUNTBLANK(Raw_Data!W$2:W$3001) -> 0 | C24: Number
A25: GenderId | B25: =COUNTBLANK(Raw_Data!X$2:X$3001) -> 0 | C25: Number
A26: IAId | B26: =COUNTBLANK(Raw_Data!Y$2:Y$3001) -> 0 | C26: Number

Sheet Cleaned_Data
A1: client_id | B1: name | C1: age | D1: location_id | E1: joined_bank | F1: banking _contact | G1: nationality | H1: occupation | I1: fee _structure | J1: loyalty_classification | K1: estimated_income | L1: superannuation_savings | M1: amount_of_credit_cards | N1: credit_card_balance | O1: bank_loans | P1: bank_deposits | Q1: checking_accounts | R1: saving_accounts | S1: foreign_currency_account | T1: business_lending | U1: properties_owned | V1: risk_weighting | W1: br_id | X1: gender_id | Y1: ia_id
A2: IND81288 | B2: Raymond Mills | C2: 24 | D2: 34324 | E2: 43591 | F2: Anthony Torres | G2: American | H2: Safety Technician IV | I2: High | J2: Jade | K2: 75384.77 | L2: 17677.95 | M2: 1 | N2: 484.54 | O2: 776242.92 | P2: 1485828.6 | Q2: 603617.88 | R2: 607332.46 | S2: 12249.96 | T2: 1134475.3 | U2: 1 | V2: 2 | W2: 1 | X2: 1 | Y2: 1
A3: IND65833 | B3: Julia Spencer | C3: 23 | D3: 42205 | E3: 37235 | F3: Jonathan Hawkins | G3: African | H3: Software Consultant | I3: High | J3: Jade | K3: 289834.31 | L3: 17398.92 | M3: 1 | N3: 2256.88 | O3: 1270615.4 | P3: 641482.79 | Q3: 229521.37 | R3: 344635.16 | S3: 61162.31 | T3: 2000526.1 | U3: 1 | V3: 3 | W3: 2 | X3: 1 | Y3: 2
A4: IND47499 | B4: Stephen Murray | C4: 27 | D4: 7314 | E4: 40203 | F4: Anthony Berry | G4: European | H4: Help Desk Operator | I4: High | J4: Gold | K4: 169935.23 | L4: 42825.9 | M4: 2 | N4: 4568.74 | O4: 1052715.8 | P4: 1033401.6 | Q4: 652674.69 | R4: 203054.35 | S4: 79071.78 | T4: 548137.58 | U4: 1 | V4: 3 | W4: 3 | X4: 2 | Y4: 3
A5: IND72498 | B5: Virginia Garza | C5: 40 | D5: 34594 | E5: 43552 | F5: Steve Diaz | G5: American | H5: Geologist II | I5: Mid | J5: Silver | K5: 356808.11 | L5: 5473.15 | M5: 2 | N5: 4205 | O5: 121195.06 | P5: 1048157.5 | Q5: 1048157.5 | R5: 234685.02 | S5: 57513.65 | T5: 1148402.3 | U5: 0 | V5: 4 | W5: 4 | X5: 1 | Y5: 4
A6: IND60181 | B6: Melissa Sanders | C6: 46 | D6: 41269 | E6: 41110 | F6: Shawn Long | G6: American | H6: Assistant Professor | I6: Mid | J6: Platinum | K6: 130711.68 | L6: 48077.6 | M6: 1 | N6: 3779.49 | O6: 1048301.9 | P6: 487782.53 | Q6: 446644.25 | R6: 128351.45 | S6: 30012.14 | T6: 1674412.1 | U6: 0 | V6: 3 | W6: 1 | X6: 2 | Y6: 5
A7: IND78532 | B7: Samuel Hudson | C7: 23 | D7: 13204 | E7: 43503 | F7: Douglas Tucker | G7: American | H7: Help Desk Technician | I7: High | J7: Silver | K7: 118326.96 | L7: 6028.2 | M7: 2 | N7: 5148.56 | O7: 601902.5 | P7: 1307269.4 | Q7: 745627.74 | R7: 238310.37 | S7: 15615.18 | T7: 1556031.1 | U7: 1 | V7: 2 | W7: 1 | X7: 1 | Y7: 6
A8: IND95683 | B8: Timothy Alexander | C8: 46 | D8: 42910 | E8: 37409 | F8: Douglas Tucker | G8: Asian | H8: Account Coordinator | I8: High | J8: Gold | K8: 57336.47 | L8: 13929.16 | M8: 1 | N8: 959.9 | O8: 208909.69 | P8: 41200.18 | Q8: 60588.5 | R8: 24639.33 | S8: 3045.78 | T8: 154111.62 | U8: 1 | V8: 1 | W8: 1 | X8: 2 | Y8: 7
A9: IND40785 | B9: Carl Martin | C9: 78 | D9: 6127 | E9: 36833 | F9: Steve Diaz | G9: European | H9: Automation Specialist II | I9: Mid | J9: Gold | K9: 65125.8 | L9: 31077.8 | M9: 1 | N9: 4576.58 | O9: 1140704.8 | P9: 156983.13 | Q9: 53889.73 | R9: 46813.78 | S9: 51979.19 | T9: 1171456.7 | U9: 0 | V9: 2 | W9: 2 | X9: 2 | Y9: 8
A10: IND13570 | B10: Philip Day | C10: 67 | D10: 32656 | E10: 42101 | F10: Bruce Butler | G10: Asian | H10: Software Test Engineer II | I10: High | J10: Silver | K10: 87849.47 | L10: 9385.35 | M10: 1 | N10: 78.62 | O10: 803444.46 | P10: 1242347.2 | Q10: 328334.62 | R10: 279528.12 | S10: 27125.28 | T10: 464560.28 | U10: 0 | V10: 1 | W10: 2 | X10: 2 | Y10: 9
A11: IND53299 | B11: Jason Sims | C11: 51 | D11: 28340 | E11: 35023 | F11: Joe Price | G11: European | H11: Geologist III | I11: Mid | J11: Silver | K11: 65369.36 | L11: 27364.8 | M11: 3 | N11: 4836.86 | O11: 60027.9 | P11: 317246.67 | Q11: 111532.03 | R11: 115869.39 | S11: 48043.52 | T11: 908583.94 | U11: 2 | V11: 1 | W11: 3 | X11: 1 | Y11: 10
A12: IND76263 | B12: Amy Martinez | C12: 55 | D12: 40459 | E12: 41930 | F12: Adam Hernandez | G12: European | H12: Administrative Officer | I12: High | J12: Jade | K12: 74966.51 | L12: 16928.73 | M12: 1 | N12: 493.32 | O12: 214327.82 | P12: 37979.77 | Q12: 19335.16 | R12: 52204.92 | S12: 10539.79 | T12: 353119.93 | U12: 3 | V12: 1 | W12: 3 | X12: 1 | Y12: 11
A13: IND56452 | B13: David Johnston | C13: 73 | D13: 25563 | E13: 38607 | F13: Chris Armstrong | G13: American | H13: Database Administrator II | I13: Mid | J13: Jade | K13: 111449.06 | L13: 17480.19 | M13: 2 | N13: 392.59 | O13: 580468.51 | P13: 749007.94 | Q13: 204991.65 | R13: 513425.24 | S13: 22904.91 | T13: 294397.85 | U13: 0 | V13: 2 | W13: 3 | X13: 2 | Y13: 12
... A3001: IND40216 | B3001: Amy Nguyen | C3001: 79 | D3001: 38518 | E3001: 38694 | F3001: Joe Hanson | G3001: American | H3001: Biostatistician III | I3001: High | J3001: Jade | K3001: 56826.53 | L3001: 8855.3 | M3001: 1 | N3001: 1494.69 | O3001: 285640.66 | P3001: 65617.66 | Q3001: 77769.08 | R3001: 32371.38 | S3001: 8992.36 | T3001: 329412.55 | U3001: 1 | V3001: 1 | W3001: 3 | X3001: 2 | Y3001: 8

Sheet EDA
A2: Customer Overview
A5: Total Customers | C5: Youngest Customer Age
A6: 3000 | C6: 17
A8: Average Age | C8: Oldest Customer Age
A9: 51.039667 | C9: 85
A11: Financial Overview
A14: Total Bank Deposits | C14: Total Bank Loans
A15: 2.0146806e+09 | C15: 1.7741585e+09
A17: Total Savings Accounts Balance | C17: Total Credit Card Balance
A18: 6.9872506e+08 | C18: 9528620.8
A20: Total Estimate Income
A21: 5.139151e+08
A23: Customer Distribution
A26: Customers by Gender
A27: Gender ID | B27: Customer Count
A28: 1 | B28: 1488
A29: 2 | B29: 1512
A30: Grand Total | B30: 3000
A32: Top 10 Occupations by Customers
A33: Occupation | B33: Customer Count
A34: Structural Analysis Engineer | B34: 28
A35: Associate Professor | B35: 28
A36: Recruiter | B36: 25
A37: Human Resources Manager | B37: 24
A38: Account Coordinator | B38: 24
A39: Assistant Professor | B39: 23
A40: Internal Auditor | B40: 23
A41: Dental Hygienist | B41: 23
A42: Database Administrator II | B42: 23
A43: Database Administrator III | B43: 23
A44: Grand Total | B44: 244
A46: Customers by Nationality
A47: Nationality | B47: Customer Count
A48: African | B48: 176
A49: American | B49: 507
A50: Asian | B50: 754
A51: Australian | B51: 254
A52: European | B52: 1309
A53: Grand Total | B53: 3000
A55: Customers by Loyalty Classification
...
